# 错误处理 
****  
## error  
> 错误处理的标准模式-`error`接口  
### 一般格式  
	type error interface {
	    Error() string
	}  
> 如果函数需要返回错误，可以将error作为返回值的最后一个  

	func foo(param int)(ret int, err error)
	{
		  ...  
	}  

### 调用`error`接口  

	n, err := foo(0)
	if err != nil {
	    //  错误处理
	} else {
	    // 使用返回值n
	}    

### 也可自定义错误类型  
	shiyanlou:~/ $ less error.go [19:52:10]
	package main
	
	import "fmt"
	import "errors"
	
	type myError struct {
	    arg int
	    errMsg string
	}
	
	func (e *myError) Error() string {
	    return fmt.Sprintf("%d - %s", e.arg, e.errMsg)
	}
	
	func error_test(arg int) (int ,error) {
	    if arg < 0 {
	        return -1, errors.New("Bad Arguments - negitive!")
	        }else if arg >256 {
	            return -1, &myError{arg, "Bad Arguments - too large!"}
	        }
	    return arg*arg, nil
	}
	
	func main() {
	    for  _, i := range []int{-1, 4, 1000} {
			if r, e := error_test(i); e != nil {
	            fmt.Println("failed!", e)
	        } else {
            fmt.Println("success;", r)
	        }
	    }
	}  
****  
	shiyanlou:~/ $ go run error.go
	failed! Bad Arguments - negitive!
	success; 16
	failed! 1000 - Bad Arguments - too large!  
****  
### defer  
> 可以添加多个`defer`语句  
> 函数执行到最后时，这些`defer`语句按照逆序执行，最后该函数返回  

	func CopyFile(dst, src string) (w int64, err error) {
	    srcFile, err := os.Open(src)
	    if err != nil {
	        return 
	    }
	
	    defer srcFile.Close()
	
		dstFile, err := os.Create(dst)
	    if err != nil {
	        return 
	    }
	
	    defer dstFile.Close()
	
	    return io.Copy(dstFile, srcFile)
	}
****  
> 也可使用一个匿名函数  

	defer func{
		...
	}  

> `defer`语句是在`return`语句之后执行的  
	shiyanlou:~/ $ go run defer.go
	12
	shiyanlou:~/ $ less defer.go
	package main
	
	import "fmt"
	
	func test() (result int) {
	    defer func() {
	        result = 12
	    }()
	    return 10
	}
	
	func main() {
	    fmt.Println(test())
	}  
****
## `panic` & `recover`语句  
> panic()函数用于抛出异常，recover()函数用于捕获异常  
### 函数原型  
	func panic(interface{})
	func recover() interface{}   
### 错误流程处理  
> 当在一个函数中调用panic()时，正常的函数执行流程将立即终止，但函数中之前使用defer关键字延迟执行的语句将正常展开执行，之后该函数将返回到调用函数，并导致逐层向上执行panic()流程，直至所属的goroutine中所有正在执行的函数被终止。错误信息将被报告，包括在调用panic()函数时传入的参数，这个过程称为错误流程处理。  

> `panic()`接受一个**任意类型**的`interface｛｝`参数  

	panic(404)
	panic("network broken")
	panic(Error("file not exists"))  
****  
	shiyanlou:~/ $ go run  error1.go[20:20:10]
	Cache Exception: i'm a bug
	0
	shiyanlou:~/ $ less error1.go [20:20:16]
	package main
	
	import(
	    "fmt"
	    "errors"
	)
	
	func foo() {
	    panic(errors.New("i'm a bug"))
	    return
	}
	
	func test() (result int){
	    defer func(){
	        if r := recover(); r != nil {
	            err := r.(error)
	            fmt.Println("Cache Exception:", err)
	        }
	    }()
	    foo()
	    return 10
	}
	
	func main() {
	    fmt.Println(test())
	}
 
****  
## [`Calculater.go`](https://blog.csdn.net/yzh900927/article/details/49556387)  
> 用Go语言编写一个可扩展的简易计算器  
****  
## 小结  
1. 学习了Go语言中错误处理的相关问题，与其他语言相比（C、C++、Java等）Go语言在错误处理上解决得更为完善  
2. 错误处理后，程序不会轻易挂掉，如果加入预警代码，可以让程序更加的健壮  
3. Go语言不支持传统的`try…catch…finally`这种处理,Go中引入的处理方式为：`defer`,`panic`和`recover`  
4. 简言之，[Go中可以抛出一个panic的异常，然后在defer中通过recover捕获这个异常，然后处理](https://blog.csdn.net/TDCQZD/article/details/82682319)  
5. 这些课程需要补充很多相关的知识，在完成实验本体之后，系统学习下Go语言编程的内容是十分有必要的  
	
